<?xml version="1.0"?>
<robot xmlns:xacro="http://www.ros.org/wiki/xacro" name="follower_bot">
  <material name="red"><color rgba="1 0 0 1"/></material>
  <material name="black"><color rgba="0 0 0 1"/></material>

  <link name="base_link">
    <visual><geometry><box size="0.4 0.3 0.1"/></geometry><material name="red"/></visual>
    <collision><geometry><box size="0.4 0.3 0.1"/></geometry></collision>
    <inertial><mass value="1.0"/><inertia ixx="0.01" ixy="0" ixz="0" iyy="0.01" iyz="0" izz="0.01"/></inertial>
  </link>

  <xacro:macro name="wheel" params="name y_offset">
    <link name="${name}">
      <visual><geometry><cylinder radius="0.1" length="0.05"/></geometry><material name="black"/></visual>
      <collision><geometry><cylinder radius="0.1" length="0.05"/></geometry></collision>
      <inertial><mass value="0.2"/><inertia ixx="0.0005" ixy="0" ixz="0" iyy="0.0005" iyz="0" izz="0.001"/></inertial>
    </link>
    <joint name="${name}_joint" type="continuous">
      <parent link="base_link"/><child link="${name}"/><origin xyz="0 ${y_offset} 0" rpy="-1.57 0 0"/><axis xyz="0 0 1"/>
    </joint>
  </xacro:macro>

  <xacro:wheel name="left_wheel" y_offset="0.18"/>
  <xacro:wheel name="right_wheel" y_offset="-0.18"/>

  <link name="camera_link"><visual><geometry><box size="0.05 0.05 0.05"/></geometry></visual></link>
  <joint name="camera_joint" type="fixed"><parent link="base_link"/><child link="camera_link"/><origin xyz="0.2 0 0.08" rpy="0 0 0"/></joint>

  <gazebo>
    <plugin filename="gz-sim-diff-drive-system" name="gz::sim::systems::DiffDrive">
      <left_joint>left_wheel_joint</left_joint><right_joint>right_wheel_joint</right_joint>
      <wheel_separation>0.36</wheel_separation><wheel_radius>0.1</wheel_radius>
      <topic>/cmd_vel</topic>
    </plugin>
    <plugin filename="gz-sim-sensors-system" name="gz::sim::systems::Sensors"><render_engine>ogre2</render_engine></plugin>
  </gazebo>
  <gazebo reference="camera_link"><sensor name="camera" type="camera"><camera><horizontal_fov>1.047</horizontal_fov><image><width>640</width><height>480</height></image></camera><always_on>1</always_on><update_rate>30</update_rate><topic>camera</topic></sensor></gazebo>
</robot>

